Workbook

Sheet Main
A1: video_id | B1: channel_id | C1: channel_title | D1: overall_score | E1: technical_depth | F1: clarity | G1: practical_value | H1: structure | I1: engagement | J1: word_count | K1: positive | L1: neutral | M1: negative
A2: 4VENens_ZU8 | B2: UCsvqVGtbbyHaMoevxPAq9Fg | C2: Simplilearn | D2: 79.2 | E2: 94 | F2: 80 | G2: 75 | H2: 84 | I2: 63 | J2: 743 | K2: 0 | L2: 100 | M2: 0
A3: pWWooQr_3ok | B3: UCCktnahuRFYIBtNnKT5IYyg | C3: Intellipaat | D3: 78.8 | E3: 88 | F3: 75 | G3: 70 | H3: 84 | I3: 77 | J3: 801 | K3: 28 | L3: 57 | M3: 14
A4: OivTPt5LQh0 | B4: UCCktnahuRFYIBtNnKT5IYyg | C4: Intellipaat | D4: 78.2 | E4: 88 | F4: 75 | G4: 70 | H4: 84 | I4: 74 | J4: 791 | K4: 22 | L4: 77 | M4: 0
A5: rQo1vkCe8OE | B5: UCZf_9SblvM8iTTkouFEcHtA | C5: Marina Wyss - AI & Machine Learning | D5: 78.2 | E5: 71 | F5: 90 | G5: 85 | H5: 84 | I5: 61 | J5: 717 | K5: 59 | L5: 30 | M5: 9
A6: RCbz5SoEIG0 | B6: UCkw4JCwteGrDHIsyIIKo4tQ | C6: edureka! | D6: 77 | E6: 92 | F6: 80 | G6: 80 | H6: 68 | I6: 65 | J6: 673 | K6: 100 | L6: 0 | M6: 0
A7: oFkygFxJ9js | B7: UCCktnahuRFYIBtNnKT5IYyg | C7: Intellipaat | D7: 75 | E7: 73 | F7: 80 | G7: 70 | H7: 80 | I7: 72 | J7: 739 | K7: 18 | L7: 75 | M7: 6
A8: sDlH-YPXd0A | B8: UCkcqmxjMXaBb0kDWqqSEU1g | C8: Sahil & Sarra | D8: 74.4 | E8: 85 | F8: 70 | G8: 80 | H8: 72 | I8: 65 | J8: 845 | K8: 26 | L8: 66 | M8: 8
A9: sDlH-YPXd0A | B9: UCkcqmxjMXaBb0kDWqqSEU1g | C9: Sahil & Sarra | D9: 74.4 | E9: 85 | F9: 70 | G9: 80 | H9: 72 | I9: 65 | J9: 845 | K9: 26 | L9: 66 | M9: 8
A10: hfLy1c2e4CE | B10: UCCktnahuRFYIBtNnKT5IYyg | C10: Intellipaat | D10: 74.2 | E10: 70 | F10: 85 | G10: 80 | H10: 80 | I10: 56 | J10: 675 | K10: 52 | L10: 48 | M10: 0
A11: hfLy1c2e4CE | B11: UCCktnahuRFYIBtNnKT5IYyg | C11: Intellipaat | D11: 74.2 | E11: 70 | F11: 85 | G11: 80 | H11: 80 | I11: 56 | J11: 675 | K11: 52 | L11: 48 | M11: 0
A12: uEfvSWM49pY | B12: UC8_RSKwbU1OmZWNEoLV1tQg | C12: Data with Baraa | D12: 73.4 | E12: 52 | F12: 80 | G12: 80 | H12: 88 | I12: 67 | J12: 753 | K12: 56 | L12: 38 | M12: 6
A13: XU5pw3QRYjQ | B13: UC8butISFwT-Wl7EV0hUK0BQ | C13: freeCodeCamp.org | D13: 73.2 | E13: 86 | F13: 75 | G13: 65 | H13: 80 | I13: 60 | J13: 925 | K13: 46 | L13: 34 | M13: 18
... A26: EZ_KDKoBBb4 | B26: UCs5Y5_7XK8HLDX0SLNwkd3w | C26: Visual Studio Code | D26: 70 | E26: 79 | F26: 75 | G26: 70 | H26: 76 | I26: 50 | J26: 976 | K26: 55 | L26: 44 | M26: 0
A27: #NAME? | B27: UCkw4JCwteGrDHIsyIIKo4tQ | C27: edureka! | D27: 69.6 | E27: 82 | F27: 70 | G27: 65 | H27: 76 | I27: 55 | J27: 790 | K27: 0 | L27: 0 | M27: 0
A28: JL_grPUnXzY | B28: UCh9nVJoWXmFb7sLApWGcLPQ | C28: codebasics | D28: 69.4 | E28: 79 | F28: 60 | G28: 70 | H28: 88 | I28: 50 | J28: 893 | K28: 28 | L28: 70 | M28: 2
A29: EeXoHhUdO8Q | B29: UC7zZ2-Q_oxbUaoMVL0z51wg | C29: Sajjaad Khader | D29: 69.4 | E29: 61 | F29: 70 | G29: 80 | H29: 76 | I29: 60 | J29: 697 | K29: 51 | L29: 32 | M29: 16
A30: LHBE6Q9XlzI | B30: UC8butISFwT-Wl7EV0hUK0BQ | C30: freeCodeCamp.org | D30: 69.2 | E30: 62 | F30: 80 | G30: 70 | H30: 76 | I30: 58 | J30: 777 | K30: 16 | L30: 70 | M30: 14
A31: HrRA67O-QXI | B31: UCs5Y5_7XK8HLDX0SLNwkd3w | C31: Visual Studio Code | D31: 69.2 | E31: 79 | F31: 80 | G31: 65 | H31: 72 | I31: 50 | J31: 973 | K31: 65 | L31: 32 | M31: 2
A32: 6rYVt_2q_BM | B32: UCCktnahuRFYIBtNnKT5IYyg | C32: Intellipaat | D32: 68.6 | E32: 67 | F32: 65 | G32: 75 | H32: 72 | I32: 64 | J32: 724 | K32: 46 | L32: 53 | M32: 0
A33: 9R3X0JoCLyU | B33: UCWv7vMbMWH4-V0ZXdmDpPBA | C33: Programming with Mosh | D33: 68.6 | E33: 91 | F33: 60 | G33: 65 | H33: 72 | I33: 55 | J33: 880 | K33: 20 | L33: 62 | M33: 18
A34: xPh5ihBWang | B34: UCkw4JCwteGrDHIsyIIKo4tQ | C34: edureka! | D34: 68.4 | E34: 73 | F34: 65 | G34: 60 | H34: 72 | I34: 72 | J34: 732 | K34: 100 | L34: 0 | M34: 0
A35: ax_NNtpSb0c | B35: UCh9nVJoWXmFb7sLApWGcLPQ | C35: codebasics | D35: 67.8 | E35: 61 | F35: 70 | G35: 70 | H35: 88 | I35: 50 | J35: 879 | K35: 14 | L35: 74 | M35: 12
A36: iMfg6Qtj8hA | B36: UCsvqVGtbbyHaMoevxPAq9Fg | C36: Simplilearn | D36: 67.2 | E36: 100 | F36: 60 | G36: 60 | H36: 68 | I36: 48 | J36: 658 | K36: 0 | L36: 50 | M36: 50
A37: 1sQDJSQBUe4 | B37: UCLLw7jmFsvfIVaUFsLs8mlQ | C37: Luke Barousse | D37: 66.8 | E37: 68 | F37: 75 | G37: 65 | H37: 76 | I37: 50 | J37: 958 | K37: 44 | L37: 44 | M37: 10
A38: Vxw0nE1qfZc | B38: UCKWaEZ-_VweaEx1j62do_vQ | C38: IBM Technology | D38: 66.8 | E38: 67 | F38: 65 | G38: 75 | H38: 72 | I38: 55 | J38: 878 | K38: 38 | L38: 42 | M38: 18
A39: mkv5mxYu0Wk | B39: UCsvqVGtbbyHaMoevxPAq9Fg | C39: Simplilearn | D39: 66.6 | E39: 70 | F39: 75 | G39: 70 | H39: 68 | I39: 50 | J39: 957 | K39: 56 | L39: 40 | M39: 4
... A72: JIbfzmt2LuY | B72: UCBwmMxybNva6P_5VmxjzwqA | C72: Apna College | D72: 62 | E72: 71 | F72: 55 | G72: 55 | H72: 74 | I72: 55 | J72: 236 | K72: 20 | L72: 73 | M72: 6
A73: #NAME? | B73: UCYA8cEWaqrpB4olR5533p5Q | C73: Anwar Haq | D73: 62 | E73: 67 | F73: 65 | G73: 50 | H73: 72 | I73: 56 | J73: 876 | K73: 0 | L73: 0 | M73: 0
A74: _4RVudwQL38 | B74: UC9Tl0-lzeDPH4y7LcRwRSQA | C74: Egor Howell | D74: 62 | E74: 61 | F74: 60 | G74: 60 | H74: 68 | I74: 61 | J74: 780 | K74: 66 | L74: 29 | M74: 3
A75: CKsuUIBW6iU | B75: UCteRPiisgIoHtMgqHegpWAQ | C75: Sundas Khalid | D75: 61.4 | E75: 61 | F75: 70 | G75: 50 | H75: 76 | I75: 50 | J75: 813 | K75: 22 | L75: 56 | M75: 22
A76: FsSrzmRawUg | B76: UCm5mt-A4w61lknZ9lCsZtBw | C76: Steve Brunton | D76: 61.4 | E76: 61 | F76: 40 | G76: 75 | H76: 76 | I76: 55 | J76: 932 | K76: 62 | L76: 33 | M76: 4
A77: 9OA757v4FAM | B77: UCteRPiisgIoHtMgqHegpWAQ | C77: Sundas Khalid | D77: 61.4 | E77: 55 | F77: 65 | G77: 65 | H77: 72 | I77: 50 | J77: 904 | K77: 52 | L77: 42 | M77: 6
A78: KxryzSO1Fjs | B78: UCsvqVGtbbyHaMoevxPAq9Fg | C78: Simplilearn | D78: 61.4 | E78: 59 | F78: 75 | G78: 60 | H78: 68 | I78: 45 | J78: 924 | K78: 83 | L78: 10 | M78: 6
A79: RBSUwFGa6Fk | B79: UCKWaEZ-_VweaEx1j62do_vQ | C79: IBM Technology | D79: 61.2 | E79: 62 | F79: 65 | G79: 45 | H79: 84 | I79: 50 | J79: 908 | K79: 46 | L79: 46 | M79: 8
A80: YJCeA8cUC90 | B80: UCh9nVJoWXmFb7sLApWGcLPQ | C80: codebasics | D80: 61.2 | E80: 55 | F80: 65 | G80: 55 | H80: 76 | I80: 55 | J80: 918 | K80: 22 | L80: 70 | M80: 6
A81: 4DlsTsqpY84 | B81: UC_fyAp919RnkKmBrMXGwnUQ | C81: Google Career Certificates | D81: 60.8 | E81: 58 | F81: 60 | G81: 60 | H81: 76 | I81: 50 | J81: 816 | K81: 43 | L81: 39 | M81: 16
A82: uakGF0DP-mk | B82: UCZf_9SblvM8iTTkouFEcHtA | C82: Marina Wyss - AI & Machine Learning | D82: 60.8 | E82: 52 | F82: 60 | G82: 70 | H82: 72 | I82: 50 | J82: 905 | K82: 56 | L82: 34 | M82: 10
A83: N6BghzuFLIg | B83: UC8butISFwT-Wl7EV0hUK0BQ | C83: freeCodeCamp.org | D83: 60.8 | E83: 62 | F83: 55 | G83: 65 | H83: 72 | I83: 50 | J83: 939 | K83: 46 | L83: 40 | M83: 14
A84: LZzq1zSL1bs | B84: UCNU_lfiiWBdtULKOw6X0Dig | C84: Krish Naik | D84: 60.8 | E84: 52 | F84: 65 | G84: 65 | H84: 72 | I84: 50 | J84: 843 | K84: 20 | L84: 52 | M84: 28
...

Sheet Sheet2
A1: video_id | B1: channel_id | C1: channel_title | D1: overall_score | E1: technical_depth | F1: clarity | G1: practical_value | H1: structure | I1: engagement | J1: word_count | K1: positive | L1: neutral | M1: negative
A2: 4VENens_ZU8 | B2: UCsvqVGtbbyHaMoevxPAq9Fg | C2: Simplilearn | D2: 79.2 | E2: 94 | F2: 80 | G2: 75 | H2: 84 | I2: 63 | J2: 743 | K2: =IFERROR(VLOOKUP(A2,Main!A:E,3,0),0) -> Simplilearn | L2: =IFERROR(VLOOKUP(A2,Main!A:E,4,0),0) -> 79.2 | M2: =IFERROR(VLOOKUP(A2,Main!A:E,5,0),0) -> 94
A3: pWWooQr_3ok | B3: UCCktnahuRFYIBtNnKT5IYyg | C3: Intellipaat | D3: 78.8 | E3: 88 | F3: 75 | G3: 70 | H3: 84 | I3: 77 | J3: 801 | K3: =IFERROR(VLOOKUP(A3,Main!A:E,3,0),0) -> Intellipaat | L3: =IFERROR(VLOOKUP(A3,Main!A:E,4,0),0) -> 78.8 | M3: =IFERROR(VLOOKUP(A3,Main!A:E,5,0),0) -> 88
A4: OivTPt5LQh0 | B4: UCCktnahuRFYIBtNnKT5IYyg | C4: Intellipaat | D4: 78.2 | E4: 88 | F4: 75 | G4: 70 | H4: 84 | I4: 74 | J4: 791 | K4: =IFERROR(VLOOKUP(A4,Main!A:E,3,0),0) -> Intellipaat | L4: =IFERROR(VLOOKUP(A4,Main!A:E,4,0),0) -> 78.2 | M4: =IFERROR(VLOOKUP(A4,Main!A:E,5,0),0) -> 88
A5: rQo1vkCe8OE | B5: UCZf_9SblvM8iTTkouFEcHtA | C5: Marina Wyss - AI & Machine Learning | D5: 78.2 | E5: 71 | F5: 90 | G5: 85 | H5: 84 | I5: 61 | J5: 717 | K5: =IFERROR(VLOOKUP(A5,Main!A:E,3,0),0) -> Marina Wyss - AI & Machine Learning | L5: =IFERROR(VLOOKUP(A5,Main!A:E,4,0),0) -> 78.2 | M5: =IFERROR(VLOOKUP(A5,Main!A:E,5,0),0) -> 71
A6: RCbz5SoEIG0 | B6: UCkw4JCwteGrDHIsyIIKo4tQ | C6: edureka! | D6: 77 | E6: 92 | F6: 80 | G6: 80 | H6: 68 | I6: 65 | J6: 673 | K6: =IFERROR(VLOOKUP(A6,Main!A:E,3,0),0) -> edureka! | L6: =IFERROR(VLOOKUP(A6,Main!A:E,4,0),0) -> 77 | M6: =IFERROR(VLOOKUP(A6,Main!A:E,5,0),0) -> 92
A7: oFkygFxJ9js | B7: UCCktnahuRFYIBtNnKT5IYyg | C7: Intellipaat | D7: 75 | E7: 73 | F7: 80 | G7: 70 | H7: 80 | I7: 72 | J7: 739 | K7: =IFERROR(VLOOKUP(A7,Main!A:E,3,0),0) -> Intellipaat | L7: =IFERROR(VLOOKUP(A7,Main!A:E,4,0),0) -> 75 | M7: =IFERROR(VLOOKUP(A7,Main!A:E,5,0),0) -> 73
A8: sDlH-YPXd0A | B8: UCkcqmxjMXaBb0kDWqqSEU1g | C8: Sahil & Sarra | D8: 74.4 | E8: 85 | F8: 70 | G8: 80 | H8: 72 | I8: 65 | J8: 845 | K8: =IFERROR(VLOOKUP(A8,Main!A:E,3,0),0) -> Sahil & Sarra | L8: =IFERROR(VLOOKUP(A8,Main!A:E,4,0),0) -> 74.4 | M8: =IFERROR(VLOOKUP(A8,Main!A:E,5,0),0) -> 85
A9: sDlH-YPXd0A | B9: UCkcqmxjMXaBb0kDWqqSEU1g | C9: Sahil & Sarra | D9: 74.4 | E9: 85 | F9: 70 | G9: 80 | H9: 72 | I9: 65 | J9: 845 | K9: =IFERROR(VLOOKUP(A9,Main!A:E,3,0),0) -> Sahil & Sarra | L9: =IFERROR(VLOOKUP(A9,Main!A:E,4,0),0) -> 74.4 | M9: =IFERROR(VLOOKUP(A9,Main!A:E,5,0),0) -> 85
A10: hfLy1c2e4CE | B10: UCCktnahuRFYIBtNnKT5IYyg | C10: Intellipaat | D10: 74.2 | E10: 70 | F10: 85 | G10: 80 | H10: 80 | I10: 56 | J10: 675 | K10: =IFERROR(VLOOKUP(A10,Main!A:E,3,0),0) -> Intellipaat | L10: =IFERROR(VLOOKUP(A10,Main!A:E,4,0),0) -> 74.2 | M10: =IFERROR(VLOOKUP(A10,Main!A:E,5,0),0) -> 70
A11: hfLy1c2e4CE | B11: UCCktnahuRFYIBtNnKT5IYyg | C11: Intellipaat | D11: 74.2 | E11: 70 | F11: 85 | G11: 80 | H11: 80 | I11: 56 | J11: 675 | K11: =IFERROR(VLOOKUP(A11,Main!A:E,3,0),0) -> Intellipaat | L11: =IFERROR(VLOOKUP(A11,Main!A:E,4,0),0) -> 74.2 | M11: =IFERROR(VLOOKUP(A11,Main!A:E,5,0),0) -> 70
A12: uEfvSWM49pY | B12: UC8_RSKwbU1OmZWNEoLV1tQg | C12: Data with Baraa | D12: 73.4 | E12: 52 | F12: 80 | G12: 80 | H12: 88 | I12: 67 | J12: 753 | K12: =IFERROR(VLOOKUP(A12,Main!A:E,3,0),0) -> Data with Baraa | L12: =IFERROR(VLOOKUP(A12,Main!A:E,4,0),0) -> 73.4 | M12: =IFERROR(VLOOKUP(A12,Main!A:E,5,0),0) -> 52
A13: XU5pw3QRYjQ | B13: UC8butISFwT-Wl7EV0hUK0BQ | C13: freeCodeCamp.org | D13: 73.2 | E13: 86 | F13: 75 | G13: 65 | H13: 80 | I13: 60 | J13: 925 | K13: =IFERROR(VLOOKUP(A13,Main!A:E,3,0),0) -> freeCodeCamp.org | L13: =IFERROR(VLOOKUP(A13,Main!A:E,4,0),0) -> 73.2 | M13: =IFERROR(VLOOKUP(A13,Main!A:E,5,0),0) -> 86
... A26: EZ_KDKoBBb4 | B26: UCs5Y5_7XK8HLDX0SLNwkd3w | C26: Visual Studio Code | D26: 70 | E26: 79 | F26: 75 | G26: 70 | H26: 76 | I26: 50 | J26: 976 | K26: =IFERROR(VLOOKUP(A26,Main!A:E,3,0),0) -> Visual Studio Code | L26: =IFERROR(VLOOKUP(A26,Main!A:E,4,0),0) -> 70 | M26: =IFERROR(VLOOKUP(A26,Main!A:E,5,0),0) -> 79
A27: =-ETQ97mXXF0 -> #NAME? | B27: UCkw4JCwteGrDHIsyIIKo4tQ | C27: edureka! | D27: 69.6 | E27: 82 | F27: 70 | G27: 65 | H27: 76 | I27: 55 | J27: 790 | K27: =IFERROR(VLOOKUP(A27,Main!A:E,3,0),0) -> 0 | L27: =IFERROR(VLOOKUP(A27,Main!A:E,4,0),0) -> 0 | M27: =IFERROR(VLOOKUP(A27,Main!A:E,5,0),0) -> 0
A28: JL_grPUnXzY | B28: UCh9nVJoWXmFb7sLApWGcLPQ | C28: codebasics | D28: 69.4 | E28: 79 | F28: 60 | G28: 70 | H28: 88 | I28: 50 | J28: 893 | K28: =IFERROR(VLOOKUP(A28,Main!A:E,3,0),0) -> codebasics | L28: =IFERROR(VLOOKUP(A28,Main!A:E,4,0),0) -> 69.4 | M28: =IFERROR(VLOOKUP(A28,Main!A:E,5,0),0) -> 79
A29: EeXoHhUdO8Q | B29: UC7zZ2-Q_oxbUaoMVL0z51wg | C29: Sajjaad Khader | D29: 69.4 | E29: 61 | F29: 70 | G29: 80 | H29: 76 | I29: 60 | J29: 697 | K29: =IFERROR(VLOOKUP(A29,Main!A:E,3,0),0) -> Sajjaad Khader | L29: =IFERROR(VLOOKUP(A29,Main!A:E,4,0),0) -> 69.4 | M29: =IFERROR(VLOOKUP(A29,Main!A:E,5,0),0) -> 61
A30: LHBE6Q9XlzI | B30: UC8butISFwT-Wl7EV0hUK0BQ | C30: freeCodeCamp.org | D30: 69.2 | E30: 62 | F30: 80 | G30: 70 | H30: 76 | I30: 58 | J30: 777 | K30: =IFERROR(VLOOKUP(A30,Main!A:E,3,0),0) -> freeCodeCamp.org | L30: =IFERROR(VLOOKUP(A30,Main!A:E,4,0),0) -> 69.2 | M30: =IFERROR(VLOOKUP(A30,Main!A:E,5,0),0) -> 62
A31: HrRA67O-QXI | B31: UCs5Y5_7XK8HLDX0SLNwkd3w | C31: Visual Studio Code | D31: 69.2 | E31: 79 | F31: 80 | G31: 65 | H31: 72 | I31: 50 | J31: 973 | K31: =IFERROR(VLOOKUP(A31,Main!A:E,3,0),0) -> Visual Studio Code | L31: =IFERROR(VLOOKUP(A31,Main!A:E,4,0),0) -> 69.2 | M31: =IFERROR(VLOOKUP(A31,Main!A:E,5,0),0) -> 79
A32: 6rYVt_2q_BM | B32: UCCktnahuRFYIBtNnKT5IYyg | C32: Intellipaat | D32: 68.6 | E32: 67 | F32: 65 | G32: 75 | H32: 72 | I32: 64 | J32: 724 | K32: =IFERROR(VLOOKUP(A32,Main!A:E,3,0),0) -> Intellipaat | L32: =IFERROR(VLOOKUP(A32,Main!A:E,4,0),0) -> 68.6 | M32: =IFERROR(VLOOKUP(A32,Main!A:E,5,0),0) -> 67
A33: 9R3X0JoCLyU | B33: UCWv7vMbMWH4-V0ZXdmDpPBA | C33: Programming with Mosh | D33: 68.6 | E33: 91 | F33: 60 | G33: 65 | H33: 72 | I33: 55 | J33: 880 | K33: =IFERROR(VLOOKUP(A33,Main!A:E,3,0),0) -> Programming with Mosh | L33: =IFERROR(VLOOKUP(A33,Main!A:E,4,0),0) -> 68.6 | M33: =IFERROR(VLOOKUP(A33,Main!A:E,5,0),0) -> 91
A34: xPh5ihBWang | B34: UCkw4JCwteGrDHIsyIIKo4tQ | C34: edureka! | D34: 68.4 | E34: 73 | F34: 65 | G34: 60 | H34: 72 | I34: 72 | J34: 732 | K34: =IFERROR(VLOOKUP(A34,Main!A:E,3,0),0) -> edureka! | L34: =IFERROR(VLOOKUP(A34,Main!A:E,4,0),0) -> 68.4 | M34: =IFERROR(VLOOKUP(A34,Main!A:E,5,0),0) -> 73
A35: ax_NNtpSb0c | B35: UCh9nVJoWXmFb7sLApWGcLPQ | C35: codebasics | D35: 67.8 | E35: 61 | F35: 70 | G35: 70 | H35: 88 | I35: 50 | J35: 879 | K35: =IFERROR(VLOOKUP(A35,Main!A:E,3,0),0) -> codebasics | L35: =IFERROR(VLOOKUP(A35,Main!A:E,4,0),0) -> 67.8 | M35: =IFERROR(VLOOKUP(A35,Main!A:E,5,0),0) -> 61
A36: iMfg6Qtj8hA | B36: UCsvqVGtbbyHaMoevxPAq9Fg | C36: Simplilearn | D36: 67.2 | E36: 100 | F36: 60 | G36: 60 | H36: 68 | I36: 48 | J36: 658 | K36: =IFERROR(VLOOKUP(A36,Main!A:E,3,0),0) -> Simplilearn | L36: =IFERROR(VLOOKUP(A36,Main!A:E,4,0),0) -> 67.2 | M36: =IFERROR(VLOOKUP(A36,Main!A:E,5,0),0) -> 100
A37: 1sQDJSQBUe4 | B37: UCLLw7jmFsvfIVaUFsLs8mlQ | C37: Luke Barousse | D37: 66.8 | E37: 68 | F37: 75 | G37: 65 | H37: 76 | I37: 50 | J37: 958 | K37: =IFERROR(VLOOKUP(A37,Main!A:E,3,0),0) -> Luke Barousse | L37: =IFERROR(VLOOKUP(A37,Main!A:E,4,0),0) -> 66.8 | M37: =IFERROR(VLOOKUP(A37,Main!A:E,5,0),0) -> 68
A38: Vxw0nE1qfZc | B38: UCKWaEZ-_VweaEx1j62do_vQ | C38: IBM Technology | D38: 66.8 | E38: 67 | F38: 65 | G38: 75 | H38: 72 | I38: 55 | J38: 878 | K38: =IFERROR(VLOOKUP(A38,Main!A:E,3,0),0) -> IBM Technology | L38: =IFERROR(VLOOKUP(A38,Main!A:E,4,0),0) -> 66.8 | M38: =IFERROR(VLOOKUP(A38,Main!A:E,5,0),0) -> 67
A39: mkv5mxYu0Wk | B39: UCsvqVGtbbyHaMoevxPAq9Fg | C39: Simplilearn | D39: 66.6 | E39: 70 | F39: 75 | G39: 70 | H39: 68 | I39: 50 | J39: 957 | K39: =IFERROR(VLOOKUP(A39,Main!A:E,3,0),0) -> Simplilearn | L39: =IFERROR(VLOOKUP(A39,Main!A:E,4,0),0) -> 66.6 | M39: =IFERROR(VLOOKUP(A39,Main!A:E,5,0),0) -> 70
... A72: JIbfzmt2LuY | B72: UCBwmMxybNva6P_5VmxjzwqA | C72: Apna College | D72: 62 | E72: 71 | F72: 55 | G72: 55 | H72: 74 | I72: 55 | J72: 236 | K72: =IFERROR(VLOOKUP(A72,Main!A:E,3,0),0) -> Apna College | L72: =IFERROR(VLOOKUP(A72,Main!A:E,4,0),0) -> 62 | M72: =IFERROR(VLOOKUP(A72,Main!A:E,5,0),0) -> 71
A73: =-gVtb3qsuJA -> #NAME? | B73: UCYA8cEWaqrpB4olR5533p5Q | C73: Anwar Haq | D73: 62 | E73: 67 | F73: 65 | G73: 50 | H73: 72 | I73: 56 | J73: 876 | K73: =IFERROR(VLOOKUP(A73,Main!A:E,3,0),0) -> 0 | L73: =IFERROR(VLOOKUP(A73,Main!A:E,4,0),0) -> 0 | M73: =IFERROR(VLOOKUP(A73,Main!A:E,5,0),0) -> 0
A74: _4RVudwQL38 | B74: UC9Tl0-lzeDPH4y7LcRwRSQA | C74: Egor Howell | D74: 62 | E74: 61 | F74: 60 | G74: 60 | H74: 68 | I74: 61 | J74: 780 | K74: =IFERROR(VLOOKUP(A74,Main!A:E,3,0),0) -> Egor Howell | L74: =IFERROR(VLOOKUP(A74,Main!A:E,4,0),0) -> 62 | M74: =IFERROR(VLOOKUP(A74,Main!A:E,5,0),0) -> 61
A75: CKsuUIBW6iU | B75: UCteRPiisgIoHtMgqHegpWAQ | C75: Sundas Khalid | D75: 61.4 | E75: 61 | F75: 70 | G75: 50 | H75: 76 | I75: 50 | J75: 813 | K75: =IFERROR(VLOOKUP(A75,Main!A:E,3,0),0) -> Sundas Khalid | L75: =IFERROR(VLOOKUP(A75,Main!A:E,4,0),0) -> 61.4 | M75: =IFERROR(VLOOKUP(A75,Main!A:E,5,0),0) -> 61
A76: FsSrzmRawUg | B76: UCm5mt-A4w61lknZ9lCsZtBw | C76: Steve Brunton | D76: 61.4 | E76: 61 | F76: 40 | G76: 75 | H76: 76 | I76: 55 | J76: 932 | K76: =IFERROR(VLOOKUP(A76,Main!A:E,3,0),0) -> Steve Brunton | L76: =IFERROR(VLOOKUP(A76,Main!A:E,4,0),0) -> 61.4 | M76: =IFERROR(VLOOKUP(A76,Main!A:E,5,0),0) -> 61
A77: 9OA757v4FAM | B77: UCteRPiisgIoHtMgqHegpWAQ | C77: Sundas Khalid | D77: 61.4 | E77: 55 | F77: 65 | G77: 65 | H77: 72 | I77: 50 | J77: 904 | K77: =IFERROR(VLOOKUP(A77,Main!A:E,3,0),0) -> Sundas Khalid | L77: =IFERROR(VLOOKUP(A77,Main!A:E,4,0),0) -> 61.4 | M77: =IFERROR(VLOOKUP(A77,Main!A:E,5,0),0) -> 55
A78: KxryzSO1Fjs | B78: UCsvqVGtbbyHaMoevxPAq9Fg | C78: Simplilearn | D78: 61.4 | E78: 59 | F78: 75 | G78: 60 | H78: 68 | I78: 45 | J78: 924 | K78: =IFERROR(VLOOKUP(A78,Main!A:E,3,0),0) -> Simplilearn | L78: =IFERROR(VLOOKUP(A78,Main!A:E,4,0),0) -> 61.4 | M78: =IFERROR(VLOOKUP(A78,Main!A:E,5,0),0) -> 59
A79: RBSUwFGa6Fk | B79: UCKWaEZ-_VweaEx1j62do_vQ | C79: IBM Technology | D79: 61.2 | E79: 62 | F79: 65 | G79: 45 | H79: 84 | I79: 50 | J79: 908 | K79: =IFERROR(VLOOKUP(A79,Main!A:E,3,0),0) -> IBM Technology | L79: =IFERROR(VLOOKUP(A79,Main!A:E,4,0),0) -> 61.2 | M79: =IFERROR(VLOOKUP(A79,Main!A:E,5,0),0) -> 62
A80: YJCeA8cUC90 | B80: UCh9nVJoWXmFb7sLApWGcLPQ | C80: codebasics | D80: 61.2 | E80: 55 | F80: 65 | G80: 55 | H80: 76 | I80: 55 | J80: 918 | K80: =IFERROR(VLOOKUP(A80,Main!A:E,3,0),0) -> codebasics | L80: =IFERROR(VLOOKUP(A80,Main!A:E,4,0),0) -> 61.2 | M80: =IFERROR(VLOOKUP(A80,Main!A:E,5,0),0) -> 55
A81: 4DlsTsqpY84 | B81: UC_fyAp919RnkKmBrMXGwnUQ | C81: Google Career Certificates | D81: 60.8 | E81: 58 | F81: 60 | G81: 60 | H81: 76 | I81: 50 | J81: 816 | K81: =IFERROR(VLOOKUP(A81,Main!A:E,3,0),0) -> Google Career Certificates | L81: =IFERROR(VLOOKUP(A81,Main!A:E,4,0),0) -> 60.8 | M81: =IFERROR(VLOOKUP(A81,Main!A:E,5,0),0) -> 58
A82: uakGF0DP-mk | B82: UCZf_9SblvM8iTTkouFEcHtA | C82: Marina Wyss - AI & Machine Learning | D82: 60.8 | E82: 52 | F82: 60 | G82: 70 | H82: 72 | I82: 50 | J82: 905 | K82: =IFERROR(VLOOKUP(A82,Main!A:E,3,0),0) -> Marina Wyss - AI & Machine Learning | L82: =IFERROR(VLOOKUP(A82,Main!A:E,4,0),0) -> 60.8 | M82: =IFERROR(VLOOKUP(A82,Main!A:E,5,0),0) -> 52
A83: N6BghzuFLIg | B83: UC8butISFwT-Wl7EV0hUK0BQ | C83: freeCodeCamp.org | D83: 60.8 | E83: 62 | F83: 55 | G83: 65 | H83: 72 | I83: 50 | J83: 939 | K83: =IFERROR(VLOOKUP(A83,Main!A:E,3,0),0) -> freeCodeCamp.org | L83: =IFERROR(VLOOKUP(A83,Main!A:E,4,0),0) -> 60.8 | M83: =IFERROR(VLOOKUP(A83,Main!A:E,5,0),0) -> 62
A84: LZzq1zSL1bs | B84: UCNU_lfiiWBdtULKOw6X0Dig | C84: Krish Naik | D84: 60.8 | E84: 52 | F84: 65 | G84: 65 | H84: 72 | I84: 50 | J84: 843 | K84: =IFERROR(VLOOKUP(A84,Main!A:E,3,0),0) -> Krish Naik | L84: =IFERROR(VLOOKUP(A84,Main!A:E,4,0),0) -> 60.8 | M84: =IFERROR(VLOOKUP(A84,Main!A:E,5,0),0) -> 52
...
